<?xml version="1.0" encoding="utf-8"?>
<!-- =================================================================================== -->
<!-- |    This document was autogenerated by xacro from curiosity_mars_rover.xacro     | -->
<!-- |    EDITING THIS FILE BY HAND IS NOT RECOMMENDED                                 | -->
<!-- =================================================================================== -->
<robot name="curiosity_mars_rover">
  <!-- ros_control plugin -->
  <gazebo>
    <plugin filename="libgazebo_ros_control.so" name="gazebo_ros_control">
      <robotNamespace>/curiosity_mars_rover</robotNamespace>
      <robotParam>/robot_description</robotParam>
      <robotSimType>gazebo_ros_control/DefaultRobotHWSim</robotSimType>
    </plugin>
  </gazebo>
  <!--
    The plugin broadcasts a body's pose and rates through ROS nav_msgs::Odometry message.
    The plugin broadcasts pose and rate of a body named "chassis" over ROS topic name "curiosity_mars_rover/odom".
  -->
  <gazebo>
    <plugin filename="libgazebo_ros_p3d.so" name="ground_truth">
      <frameName>world</frameName>
      <bodyName>chassis</bodyName>
      <topicName>/curiosity_mars_rover/odom</topicName>
      <updateRate>30.0</updateRate>
    </plugin>
  </gazebo>
  <gazebo reference="camera_link">
    <sensor name="camera1" type="depth">
      <update_rate>10.0</update_rate>
      <camera name="head">
        <pose>0 0 0 0 0 1.57</pose>
        <horizontal_fov>1.3962634</horizontal_fov>
        <image>
          <width>800</width>
          <height>800</height>
          <format>R8G8B8</format>
        </image>
        <clip>
          <near>0.01</near>
          <far>100</far>
        </clip>
        <noise>
          <type>gaussian</type>
          <stddev>0.007</stddev>
        </noise>
      </camera>
      <plugin filename="libgazebo_ros_openni_kinect.so" name="depthcamera_controller">
        <baseline>0.2</baseline>
        <alwaysOn>true</alwaysOn>
        <updateRate>1.0</updateRate>
        <cameraName>depthcamera</cameraName>
        <imageTopicName>/depthcamera/depth/image_raw</imageTopicName>
        <cameraInfoTopicName>/depthcamera/depth/camera_info</cameraInfoTopicName>
        <depthImageTopicName>/depthcamera/depth/image_raw</depthImageTopicName>
        <depthImageInfoTopicName>/depthcamera/depth/camera_info</depthImageInfoTopicName>
        <pointCloudTopicName>/depthcamera/depth/points</pointCloudTopicName>
        <frameName>pointcloud_link</frameName>
        <pointCloudCutoff>0.5</pointCloudCutoff>
        <pointCloudCutoffMax>3.0</pointCloudCutoffMax>
        <distortionK1>0.00000001</distortionK1>
        <distortionK2>0.00000001</distortionK2>
        <distortionK3>0.00000001</distortionK3>
        <distortionT1>0.00000001</distortionT1>
        <distortionT2>0.00000001</distortionT2>
        <CxPrime>0</CxPrime>
        <Cx>0</Cx>
        <Cy>0</Cy>
        <focalLength>0</focalLength>
        <hackBaseline>0</hackBaseline>
      </plugin>
    </sensor>
  </gazebo>
  <link name="pointcloud_link"/>
  <joint name="pointcloud_joint" type="fixed">
    <axis xyz="0 0 0"/>
    <origin rpy="-1.58 0 0" xyz="0 0 0"/>
    <parent link="camera_link"/>
    <child link="pointcloud_link"/>
  </joint>
  <!--
  <gazebo reference="depthcamera_link">
    <sensor name="depthcamera" type="depth">
      <update_rate>10.0</update_rate>
      <camera name = "depth">
        <pose>0 0 0 0 0 .57</pose>
        <horizontal_fov>1.047198</horizontal_fov>
        <image>
          <width>640</width>
          <height>480</height>
          <format>R8G8B8</format>
        </image>
        <clip>
          <near>0.05</near>
          <far>3</far>
        </clip>
      </camera>
      <plugin name="depthcamera_controller" filename="libgazebo_ros_openni_kinect.so">
        <baseline>0.2</baseline>
        <alwaysOn>true</alwaysOn>
        <updateRate>1.0</updateRate>
        <cameraName>depthcamera</cameraName>
        <imageTopicName>/depthcamera/depth/image_raw</imageTopicName>
        <cameraInfoTopicName>/depthcamera/depth/camera_info</cameraInfoTopicName>
        <depthImageTopicName>/depthcamera/depth/image_raw</depthImageTopicName>
        <depthImageInfoTopicName>/depthcamera/depth/camera_info</depthImageInfoTopicName>
        <pointCloudTopicName>/depthcamera/depth/points</pointCloudTopicName>
        <frameName>pointcloud_link</frameName>
        <pointCloudCutoff>0.5</pointCloudCutoff>
        <pointCloudCutoffMax>3.0</pointCloudCutoffMax>
        <distortionK1>0.00000001</distortionK1>
        <distortionK2>0.00000001</distortionK2>
        <distortionK3>0.00000001</distortionK3>
        <distortionT1>0.00000001</distortionT1>
        <distortionT2>0.00000001</distortionT2>
        <CxPrime>0</CxPrime>
        <Cx>0</Cx>
        <Cy>0</Cy>
        <focalLength>0</focalLength>
        <hackBaseline>0</hackBaseline>
      </plugin>
    </sensor>
  </gazebo>

-->
  <!-- stereo camera -->
  <gazebo reference="camera_link">
    <sensor name="stereo_camera" type="multicamera">
      <update_rate>10.0</update_rate>
      <camera name="left">
        <pose>0 0 0 0 0 1.57</pose>
        <horizontal_fov>1.3962634</horizontal_fov>
        <image>
          <width>800</width>
          <height>800</height>
          <format>R8G8B8</format>
        </image>
        <clip>
          <near>0.034</near>
          <far>100</far>
        </clip>
        <noise>
          <type>gaussian</type>
          <mean>0.0</mean>
          <stddev>0.007</stddev>
        </noise>
      </camera>
      <camera name="right">
        <pose>.25 0 0 0 0 1.57</pose>
        <horizontal_fov>1.3962634</horizontal_fov>
        <image>
          <width>800</width>
          <height>800</height>
          <format>R8G8B8</format>
        </image>
        <clip>
          <near>0.1</near>
          <far>100</far>
        </clip>
        <noise>
          <type>gaussian</type>
          <mean>0.0</mean>
          <stddev>0.007</stddev>
        </noise>
      </camera>
      <plugin filename="libgazebo_ros_multicamera.so" name="stereo_camera_controller">
        <alwaysOn>true</alwaysOn>
        <updateRate>0.0</updateRate>
        <cameraName>mira/camera2</cameraName>
        <imageTopicName>image_raw</imageTopicName>
        <cameraInfoTopicName>camera_info</cameraInfoTopicName>
        <frameName>camera_link</frameName>
        <hackBaseline>0.07</hackBaseline>
        <distortionK1>0.0</distortionK1>
        <distortionK2>0.0</distortionK2>
        <distortionK3>0.0</distortionK3>
        <distortionT1>0.0</distortionT1>
        <distortionT2>0.0</distortionT2>
      </plugin>
    </sensor>
  </gazebo>
  <!-- Chassis -->
  <gazebo reference="chassis">
    <mu1>0.3</mu1>
    <mu2>0.3</mu2>
  </gazebo>
  <!-- Wheel Train -->
  <gazebo reference="left_axis">
    <mu1>0.3</mu1>
    <mu2>0.3</mu2>
  </gazebo>
  <gazebo reference="suspension_arm_F_L">
    <mu1>0.3</mu1>
    <mu2>0.3</mu2>
  </gazebo>
  <gazebo reference="right_axis">
    <mu1>0.3</mu1>
    <mu2>0.3</mu2>
  </gazebo>
  <gazebo reference="suspension_arm_F_R">
    <mu1>0.3</mu1>
    <mu2>0.3</mu2>
  </gazebo>
  <gazebo reference="suspension_arm_B_L">
    <mu1>0.3</mu1>
    <mu2>0.3</mu2>
  </gazebo>
  <gazebo reference="suspension_arm_B_R">
    <mu1>0.3</mu1>
    <mu2>0.3</mu2>
  </gazebo>
  <gazebo reference="suspension_arm_B_L_to_B2_L">
    <mu1>0.3</mu1>
    <mu2>0.3</mu2>
    <material>Gazebo/Black</material>
  </gazebo>
  <gazebo reference="suspension_arm_B_R_to_B2_R">
    <mu1>0.3</mu1>
    <mu2>0.3</mu2>
    <material>Gazebo/Black</material>
  </gazebo>
  <gazebo reference="suspension_arm_B2_L">
    <mu1>0.3</mu1>
    <mu2>0.3</mu2>
  </gazebo>
  <gazebo reference="suspension_arm_B2_R">
    <mu1>0.3</mu1>
    <mu2>0.3</mu2>
  </gazebo>
  <gazebo reference="suspension_arm_F_L_to_suspension_steer_F_L">
    <mu1>0.3</mu1>
    <mu2>0.3</mu2>
  </gazebo>
  <gazebo reference="suspension_arm_F_R_to_suspension_steer_F_R">
    <mu1>0.3</mu1>
    <mu2>0.3</mu2>
  </gazebo>
  <gazebo reference="suspension_steer_F_L">
    <mu1>0.3</mu1>
    <mu2>0.3</mu2>
  </gazebo>
  <gazebo reference="suspension_steer_F_R">
    <mu1>0.3</mu1>
    <mu2>0.3</mu2>
  </gazebo>
  <gazebo reference="suspension_arm_B2_L_to_suspension_steer_B_L">
    <mu1>0.3</mu1>
    <mu2>0.3</mu2>
  </gazebo>
  <gazebo reference="suspension_arm_B2_R_to_suspension_steer_B_R">
    <mu1>0.3</mu1>
    <mu2>0.3</mu2>
  </gazebo>
  <gazebo reference="suspension_steer_B_L">
    <mu1>0.3</mu1>
    <mu2>0.3</mu2>
  </gazebo>
  <gazebo reference="suspension_steer_B_R">
    <mu1>0.3</mu1>
    <mu2>0.3</mu2>
  </gazebo>
  <!-- Arm -->
  <gazebo reference="arm_01">
    <mu1>0.3</mu1>
    <mu2>0.3</mu2>
  </gazebo>
  <!-- Used for fixing robot to Gazebo 'chassis' -->
  <link name="base_footprint"/>
  <joint name="base_joint" type="fixed">
    <parent link="base_footprint"/>
    <child link="chassis"/>
  </joint>
  <link name="chassis">
    <collision>
      <origin rpy="0 0 0" xyz="0 0 0"/>
      <geometry>
        <mesh filename="package://curiosity_mars_rover_description/meshes/chassis_full_fixed_glitch_v2.dae" scale="1.0 1.0 1.0"/>
      </geometry>
    </collision>
    <visual>
      <origin rpy="0 0 0" xyz="0 0 0"/>
      <geometry>
        <mesh filename="package://curiosity_mars_rover_description/meshes/chassis_full_fixed_glitch_v2.dae" scale="1.0 1.0 1.0"/>
      </geometry>
    </visual>
    <inertial>
      <origin rpy="0 0 0" xyz="0 0 0"/>
      <mass value="733.64"/>
      <inertia ixx="300.213659826" ixy="0" ixz="0" iyy="179.879009486" iyz="0" izz="179.879009486"/>
    </inertial>
  </link>
  <link name="left_axis">
    <collision>
      <origin rpy="0 0 0" xyz="0 0 0"/>
      <geometry>
        <mesh filename="package://curiosity_mars_rover_description/meshes/left_axis_jointfix_v2.dae" scale="1.0 1.0 1.0"/>
      </geometry>
    </collision>
    <visual>
      <origin rpy="0 0 0" xyz="0 0 0"/>
      <geometry>
        <mesh filename="package://curiosity_mars_rover_description/meshes/left_axis_jointfix_v2.dae" scale="1.0 1.0 1.0"/>
      </geometry>
    </visual>
    <inertial>
      <origin rpy="0 0 0" xyz="0 0 0"/>
      <mass value="7.296"/>
      <inertia ixx="0.105611398768" ixy="0" ixz="0" iyy="0.125057783795" iyz="0" izz="0.125057783795"/>
    </inertial>
  </link>
  <joint name="left_axis_joint" type="fixed">
    <parent link="chassis"/>
    <child link="left_axis"/>
    <origin rpy="0 -0.19565141 0" xyz="0.7938 -0.2133 0"/>
  </joint>
  <link name="suspension_arm_F_L">
    <collision>
      <origin rpy="0 0 0" xyz="0 0 0"/>
      <geometry>
        <mesh filename="package://curiosity_mars_rover_description/meshes/suspension_arm_F_L_fixed.dae" scale="1.0 1.0 1.0"/>
      </geometry>
    </collision>
    <visual>
      <origin rpy="0 0 0" xyz="0 0 0"/>
      <geometry>
        <mesh filename="package://curiosity_mars_rover_description/meshes/suspension_arm_F_L_fixed.dae" scale="1.0 1.0 1.0"/>
      </geometry>
    </visual>
    <inertial>
      <origin rpy="0 0 0" xyz="0 0 0"/>
      <mass value="7.296"/>
      <inertia ixx="0.691776350704" ixy="0" ixz="0" iyy="0.152065817946" iyz="0" izz="0.152065817946"/>
    </inertial>
  </link>
  <joint name="suspension_arm_F_L_joint" type="revolute">
    <parent link="left_axis"/>
    <child link="suspension_arm_F_L"/>
    <origin rpy="0 0 0" xyz="0 0 0"/>
    <limit effort="10000.0" lower="-0.4" upper="0.4" velocity="10.0"/>
    <axis xyz="1 0 0"/>
    <joint_properties damping="0.5" friction="0.5"/>
  </joint>
  <transmission name="suspension_arm_F_L_trans">
    <type>transmission_interface/SimpleTransmission</type>
    <joint name="suspension_arm_F_L_joint">
      <hardwareInterface>hardware_interface/EffortJointInterface</hardwareInterface>
    </joint>
    <actuator name="suspension_arm_F_LMotor">
      <hardwareInterface>hardware_interface/EffortJointInterface</hardwareInterface>
      <mechanicalReduction>1</mechanicalReduction>
    </actuator>
  </transmission>
  <link name="suspension_arm_B_L">
    <collision>
      <origin rpy="0 0 0" xyz="0 0 0"/>
      <geometry>
        <mesh filename="package://curiosity_mars_rover_description/meshes/suspension_arm_B_L_fixed.dae" scale="1.0 1.0 1.0"/>
      </geometry>
    </collision>
    <visual>
      <origin rpy="0 0 0" xyz="0 0 0"/>
      <geometry>
        <mesh filename="package://curiosity_mars_rover_description/meshes/suspension_arm_B_L_fixed.dae" scale="1.0 1.0 1.0"/>
      </geometry>
    </visual>
    <inertial>
      <origin rpy="0 0 0" xyz="0 0 0"/>
      <mass value="7.296"/>
      <inertia ixx="0.515242640212" ixy="0" ixz="0" iyy="0.0830580822383" iyz="0" izz="0.0830580822383"/>
    </inertial>
  </link>
  <joint name="suspension_arm_B_L_joint" type="revolute">
    <parent link="left_axis"/>
    <child link="suspension_arm_B_L"/>
    <origin rpy="0 0 0" xyz="0 0 0"/>
    <limit effort="10000.0" lower="-0.4" upper="0.4" velocity="10.0"/>
    <axis xyz="1 0 0"/>
    <joint_properties damping="0.5" friction="0.5"/>
  </joint>
  <transmission name="suspension_arm_B_L_trans">
    <type>transmission_interface/SimpleTransmission</type>
    <joint name="suspension_arm_B_L_joint">
      <hardwareInterface>hardware_interface/EffortJointInterface</hardwareInterface>
    </joint>
    <actuator name="suspension_arm_B_LMotor">
      <hardwareInterface>hardware_interface/EffortJointInterface</hardwareInterface>
      <mechanicalReduction>1</mechanicalReduction>
    </actuator>
  </transmission>
  <link name="suspension_arm_B_L_to_B2_L">
    <inertial>
      <origin rpy="0 0 0" xyz="0 0 0"/>
      <mass value="0.02"/>
      <inertia ixx="2.61666666667e-05" ixy="0.0" ixz="0.0" iyy="2.61666666667e-05" iyz="0.0" izz="3.6e-05"/>
    </inertial>
    <collision>
      <origin rpy="0 0 0" xyz="0 0 0.015"/>
      <geometry>
        <cylinder length="0.035" radius="0.06"/>
      </geometry>
    </collision>
    <visual>
      <origin rpy="0.0 1.57 0" xyz="0 0 0"/>
      <geometry>
        <cylinder length="0.1" radius="0.04"/>
      </geometry>
    </visual>
  </link>
  <joint name="suspension_arm_B_L_to_B2_L_joint" type="fixed">
    <parent link="suspension_arm_B_L"/>
    <child link="suspension_arm_B_L_to_B2_L"/>
    <origin rpy="0 0.1937315 0" xyz="-0.05159 0.73683 -0.22972"/>
  </joint>
  <link name="suspension_arm_B2_L">
    <collision>
      <origin rpy="0 0 0" xyz="0 0 0"/>
      <geometry>
        <mesh filename="package://curiosity_mars_rover_description/meshes/suspension_arm_B2_L_fixed.dae" scale="1.0 1.0 1.0"/>
      </geometry>
    </collision>
    <visual>
      <origin rpy="0 0 0" xyz="0 0 0"/>
      <geometry>
        <mesh filename="package://curiosity_mars_rover_description/meshes/suspension_arm_B2_L_fixed.dae" scale="1.0 1.0 1.0"/>
      </geometry>
    </visual>
    <inertial>
      <origin rpy="0 0 0" xyz="0 0 0"/>
      <mass value="7.296"/>
      <inertia ixx="1.14896565746" ixy="0" ixz="0" iyy="0.339748782044" iyz="0" izz="0.339748782044"/>
    </inertial>
  </link>
  <joint name="suspension_arm_B2_L_joint" type="revolute">
    <parent link="suspension_arm_B_L_to_B2_L"/>
    <child link="suspension_arm_B2_L"/>
    <origin rpy="0 0 0" xyz="0 0 0"/>
    <limit effort="10000.0" lower="-1.2" upper="0.1" velocity="10.0"/>
    <axis xyz="1 0 0"/>
    <joint_properties damping="0.5" friction="0.5"/>
  </joint>
  <transmission name="suspension_arm_B2_L_trans">
    <type>transmission_interface/SimpleTransmission</type>
    <joint name="suspension_arm_B2_L_joint">
      <hardwareInterface>hardware_interface/EffortJointInterface</hardwareInterface>
    </joint>
    <actuator name="suspension_arm_B2_LMotor">
      <hardwareInterface>hardware_interface/EffortJointInterface</hardwareInterface>
      <mechanicalReduction>1</mechanicalReduction>
    </actuator>
  </transmission>
  <!-- FRONT WHEEL -->
  <link name="suspension_arm_F_L_to_suspension_steer_F_L">
    <inertial>
      <origin rpy="0 0 0" xyz="0 0 0"/>
      <mass value="0.02"/>
      <inertia ixx="2.61666666667e-05" ixy="0.0" ixz="0.0" iyy="2.61666666667e-05" iyz="0.0" izz="3.6e-05"/>
    </inertial>
    <collision>
      <origin rpy="0 0 0" xyz="0 0 0.015"/>
      <geometry>
        <cylinder length="0.04" radius="0.06"/>
      </geometry>
    </collision>
    <visual>
      <origin rpy="0.0 0 0" xyz="0 0 0"/>
      <geometry>
        <cylinder length="0.04" radius="0.06"/>
      </geometry>
    </visual>
  </link>
  <joint name="suspension_arm_F_L_to_suspension_steer_F_L_joint" type="fixed">
    <parent link="suspension_arm_F_L"/>
    <child link="suspension_arm_F_L_to_suspension_steer_F_L"/>
    <origin rpy="0 0.1937315 0" xyz="0.2057 -0.87876 -0.29370"/>
  </joint>
  <link name="suspension_steer_F_L">
    <collision>
      <origin rpy="0 0 0" xyz="0 0 0"/>
      <geometry>
        <mesh filename="package://curiosity_mars_rover_description/meshes/suspension_steer_F_L_fixed.dae" scale="1.0 1.0 1.0"/>
      </geometry>
    </collision>
    <visual>
      <origin rpy="0 0 0" xyz="0 0 0"/>
      <geometry>
        <mesh filename="package://curiosity_mars_rover_description/meshes/suspension_steer_F_L_fixed.dae" scale="1.0 1.0 1.0"/>
      </geometry>
    </visual>
    <inertial>
      <origin rpy="0 0 0" xyz="0 0 0"/>
      <mass value="7.296"/>
      <inertia ixx="0.150001040337" ixy="0" ixz="0" iyy="0.292896645934" iyz="0" izz="0.292896645934"/>
    </inertial>
  </link>
  <joint name="suspension_steer_F_L_joint" type="revolute">
    <parent link="suspension_arm_F_L_to_suspension_steer_F_L"/>
    <child link="suspension_steer_F_L"/>
    <origin rpy="0 0 0" xyz="0 0 0"/>
    <limit effort="10000.0" lower="-0.6" upper="0.6" velocity="10.0"/>
    <axis xyz="0 0 1"/>
  </joint>
  <transmission name="suspension_steer_F_L_trans">
    <type>transmission_interface/SimpleTransmission</type>
    <joint name="suspension_steer_F_L_joint">
      <hardwareInterface>hardware_interface/EffortJointInterface</hardwareInterface>
    </joint>
    <actuator name="suspension_steer_F_LMotor">
      <hardwareInterface>hardware_interface/EffortJointInterface</hardwareInterface>
      <mechanicalReduction>1</mechanicalReduction>
    </actuator>
  </transmission>
  <link name="suspension_steer_F_L_to_front_wheel_L">
    <inertial>
      <origin rpy="0 0 0" xyz="0 0 0"/>
      <mass value="0.02"/>
      <inertia ixx="2.61666666667e-05" ixy="0.0" ixz="0.0" iyy="2.61666666667e-05" iyz="0.0" izz="3.6e-05"/>
    </inertial>
    <collision>
      <origin rpy="0.0 1.57 0" xyz="0 0 0"/>
      <geometry>
        <cylinder length="0.02" radius="0.02"/>
      </geometry>
    </collision>
    <visual>
      <origin rpy="0.0 1.57 0" xyz="0 0 0"/>
      <geometry>
        <cylinder length="0.02" radius="0.02"/>
      </geometry>
    </visual>
  </link>
  <joint name="suspension_steer_F_L_to_suspension_steer_F_L_to_front_wheel_L_joint" type="fixed">
    <parent link="suspension_steer_F_L"/>
    <child link="suspension_steer_F_L_to_front_wheel_L"/>
    <origin rpy="0 0 0" xyz="0 0 -0.3996"/>
  </joint>
  <!-- tY is Zero if left side, 1 if right side -->
  <link name="front_wheel_L">
    <collision>
      <origin rpy="0 1.57 0" xyz="0 0 0"/>
      <geometry>
        <cylinder length="0.39473" radius="0.242647"/>
      </geometry>
    </collision>
    <visual>
      <origin rpy="0 0 0" xyz="0 0 0"/>
      <geometry>
        <mesh filename="package://curiosity_mars_rover_description/meshes/wheel_fixed.dae" scale="1.0 1.0 1.0"/>
      </geometry>
    </visual>
    <inertial>
      <origin rpy="0 0 0" xyz="0 0 0"/>
      <mass value="2.07"/>
      <inertia ixx="0.0573466715454" ixy="0" ixz="0" iyy="0.0573466715454" iyz="0" izz="0.0609382814403"/>
    </inertial>
  </link>
  <gazebo reference="front_wheel_L">
    <mu1 value="1.0"/>
    <mu2 value="1.0"/>
    <kp value="10000000.0"/>
    <kd>100.0</kd>
    <minDepth>0.001</minDepth>
    <maxVel>1.0</maxVel>
    <!--kd  value="1.0" />
      <fdir1 value="1 0 0"/-->
  </gazebo>
  <joint name="front_wheel_L_joint" type="continuous">
    <parent link="suspension_steer_F_L_to_front_wheel_L"/>
    <child link="front_wheel_L"/>
    <origin rpy="0 0 0.0" xyz="0 0 0"/>
    <limit effort="10000.0" velocity="100.0"/>
    <axis xyz="1 0 0"/>
    <joint_properties damping="0.0" friction="0.0"/>
  </joint>
  <transmission name="front_wheel_L_trans">
    <type>transmission_interface/SimpleTransmission</type>
    <joint name="front_wheel_L_joint">
      <hardwareInterface>hardware_interface/EffortJointInterface</hardwareInterface>
    </joint>
    <actuator name="front_wheel_LMotor">
      <hardwareInterface>hardware_interface/EffortJointInterface</hardwareInterface>
      <mechanicalReduction>1</mechanicalReduction>
    </actuator>
  </transmission>
  <!-- FRONT LEFT Wheel Left END -->
  <!-- MIDDLE WHEEL -->
  <link name="suspension_arm_B2_L_to_middle_wheel_L">
    <inertial>
      <origin rpy="0 0 0" xyz="0 0 0"/>
      <mass value="0.02"/>
      <inertia ixx="2.61666666667e-05" ixy="0.0" ixz="0.0" iyy="2.61666666667e-05" iyz="0.0" izz="3.6e-05"/>
    </inertial>
    <collision>
      <origin rpy="0.0 1.57 0" xyz="0 0 0"/>
      <geometry>
        <cylinder length="0.02" radius="0.02"/>
      </geometry>
    </collision>
    <visual>
      <origin rpy="0.0 1.57 0" xyz="0 0 0"/>
      <geometry>
        <cylinder length="0.02" radius="0.02"/>
      </geometry>
    </visual>
  </link>
  <joint name="suspension_arm_B2_L_to_suspension_arm_B2_L_to_middle_wheel_L_joint" type="fixed">
    <parent link="suspension_arm_B2_L"/>
    <child link="suspension_arm_B2_L_to_middle_wheel_L"/>
    <origin rpy="0 0 0" xyz="0.39423 -0.44859 -0.41098"/>
  </joint>
  <!-- tY is Zero if left side, 1 if right side -->
  <link name="middle_wheel_L">
    <collision>
      <origin rpy="0 1.57 0" xyz="0 0 0"/>
      <geometry>
        <cylinder length="0.39473" radius="0.242647"/>
      </geometry>
    </collision>
    <visual>
      <origin rpy="0 0 0" xyz="0 0 0"/>
      <geometry>
        <mesh filename="package://curiosity_mars_rover_description/meshes/wheel_fixed.dae" scale="1.0 1.0 1.0"/>
      </geometry>
    </visual>
    <inertial>
      <origin rpy="0 0 0" xyz="0 0 0"/>
      <mass value="2.07"/>
      <inertia ixx="0.0573466715454" ixy="0" ixz="0" iyy="0.0573466715454" iyz="0" izz="0.0609382814403"/>
    </inertial>
  </link>
  <gazebo reference="middle_wheel_L">
    <mu1 value="1.0"/>
    <mu2 value="1.0"/>
    <kp value="10000000.0"/>
    <kd>100.0</kd>
    <minDepth>0.001</minDepth>
    <maxVel>1.0</maxVel>
    <!--kd  value="1.0" />
      <fdir1 value="1 0 0"/-->
  </gazebo>
  <joint name="middle_wheel_L_joint" type="continuous">
    <parent link="suspension_arm_B2_L_to_middle_wheel_L"/>
    <child link="middle_wheel_L"/>
    <origin rpy="0 0 0.0" xyz="0 0 0"/>
    <limit effort="10000.0" velocity="100.0"/>
    <axis xyz="1 0 0"/>
    <joint_properties damping="0.0" friction="0.0"/>
  </joint>
  <transmission name="middle_wheel_L_trans">
    <type>transmission_interface/SimpleTransmission</type>
    <joint name="middle_wheel_L_joint">
      <hardwareInterface>hardware_interface/EffortJointInterface</hardwareInterface>
    </joint>
    <actuator name="middle_wheel_LMotor">
      <hardwareInterface>hardware_interface/EffortJointInterface</hardwareInterface>
      <mechanicalReduction>1</mechanicalReduction>
    </actuator>
  </transmission>
  <!-- FRONT MIDDLE Wheel Left END -->
  <!-- BACK WHEEL -->
  <link name="suspension_arm_B2_L_to_suspension_steer_B_L">
    <inertial>
      <origin rpy="0 0 0" xyz="0 0 0"/>
      <mass value="0.02"/>
      <inertia ixx="2.61666666667e-05" ixy="0.0" ixz="0.0" iyy="2.61666666667e-05" iyz="0.0" izz="3.6e-05"/>
    </inertial>
    <collision>
      <origin rpy="0 0 0" xyz="0 0 0.015"/>
      <geometry>
        <cylinder length="0.04" radius="0.06"/>
      </geometry>
    </collision>
    <visual>
      <origin rpy="0.0 0 0" xyz="0 0 0"/>
      <geometry>
        <cylinder length="0.04" radius="0.06"/>
      </geometry>
    </visual>
  </link>
  <joint name="suspension_arm_B2_L_to_suspension_steer_B_L_joint" type="fixed">
    <parent link="suspension_arm_B2_L"/>
    <child link="suspension_arm_B2_L_to_suspension_steer_B_L"/>
    <origin rpy="0 0 0" xyz="0.26271 0.62363 -0.00069"/>
  </joint>
  <link name="suspension_steer_B_L">
    <collision>
      <origin rpy="0 0 0" xyz="0 0 0"/>
      <geometry>
        <mesh filename="package://curiosity_mars_rover_description/meshes/suspension_steer_B_L_fixed.dae" scale="1.0 1.0 1.0"/>
      </geometry>
    </collision>
    <visual>
      <origin rpy="0 0 0" xyz="0 0 0"/>
      <geometry>
        <mesh filename="package://curiosity_mars_rover_description/meshes/suspension_steer_B_L_fixed.dae" scale="1.0 1.0 1.0"/>
      </geometry>
    </visual>
    <inertial>
      <origin rpy="0 0 0" xyz="0 0 0"/>
      <mass value="7.296"/>
      <inertia ixx="0.150001040337" ixy="0" ixz="0" iyy="0.292896645934" iyz="0" izz="0.292896645934"/>
    </inertial>
  </link>
  <joint name="suspension_steer_B_L_joint" type="revolute">
    <parent link="suspension_arm_B2_L_to_suspension_steer_B_L"/>
    <child link="suspension_steer_B_L"/>
    <origin rpy="0 0 0" xyz="0 0 0"/>
    <limit effort="10000.0" lower="-0.6" upper="0.6" velocity="10.0"/>
    <axis xyz="0 0 1"/>
  </joint>
  <transmission name="suspension_steer_B_L_trans">
    <type>transmission_interface/SimpleTransmission</type>
    <joint name="suspension_steer_B_L_joint">
      <hardwareInterface>hardware_interface/EffortJointInterface</hardwareInterface>
    </joint>
    <actuator name="suspension_steer_B_LMotor">
      <hardwareInterface>hardware_interface/EffortJointInterface</hardwareInterface>
      <mechanicalReduction>1</mechanicalReduction>
    </actuator>
  </transmission>
  <link name="suspension_steer_B_L_to_back_wheel_L">
    <inertial>
      <origin rpy="0 0 0" xyz="0 0 0"/>
      <mass value="0.02"/>
      <inertia ixx="2.61666666667e-05" ixy="0.0" ixz="0.0" iyy="2.61666666667e-05" iyz="0.0" izz="3.6e-05"/>
    </inertial>
    <collision>
      <origin rpy="0.0 1.57 0" xyz="0 0 0"/>
      <geometry>
        <cylinder length="0.02" radius="0.02"/>
      </geometry>
    </collision>
    <visual>
      <origin rpy="0.0 1.57 0" xyz="0 0 0"/>
      <geometry>
        <cylinder length="0.02" radius="0.02"/>
      </geometry>
    </visual>
  </link>
  <joint name="suspension_arm_B2_L_to_suspension_steer_B_L_to_back_wheel_L_joint" type="fixed">
    <parent link="suspension_steer_B_L"/>
    <child link="suspension_steer_B_L_to_back_wheel_L"/>
    <origin rpy="0 0 0" xyz="0 0 -0.410523"/>
  </joint>
  <!-- tY is Zero if left side, 1 if right side -->
  <link name="back_wheel_L">
    <collision>
      <origin rpy="0 1.57 0" xyz="0 0 0"/>
      <geometry>
        <cylinder length="0.39473" radius="0.242647"/>
      </geometry>
    </collision>
    <visual>
      <origin rpy="0 0 0" xyz="0 0 0"/>
      <geometry>
        <mesh filename="package://curiosity_mars_rover_description/meshes/wheel_fixed.dae" scale="1.0 1.0 1.0"/>
      </geometry>
    </visual>
    <inertial>
      <origin rpy="0 0 0" xyz="0 0 0"/>
      <mass value="2.07"/>
      <inertia ixx="0.0573466715454" ixy="0" ixz="0" iyy="0.0573466715454" iyz="0" izz="0.0609382814403"/>
    </inertial>
  </link>
  <gazebo reference="back_wheel_L">
    <mu1 value="1.0"/>
    <mu2 value="1.0"/>
    <kp value="10000000.0"/>
    <kd>100.0</kd>
    <minDepth>0.001</minDepth>
    <maxVel>1.0</maxVel>
    <!--kd  value="1.0" />
      <fdir1 value="1 0 0"/-->
  </gazebo>
  <joint name="back_wheel_L_joint" type="continuous">
    <parent link="suspension_steer_B_L_to_back_wheel_L"/>
    <child link="back_wheel_L"/>
    <origin rpy="0 0 0.0" xyz="0 0 0"/>
    <limit effort="10000.0" velocity="100.0"/>
    <axis xyz="1 0 0"/>
    <joint_properties damping="0.0" friction="0.0"/>
  </joint>
  <transmission name="back_wheel_L_trans">
    <type>transmission_interface/SimpleTransmission</type>
    <joint name="back_wheel_L_joint">
      <hardwareInterface>hardware_interface/EffortJointInterface</hardwareInterface>
    </joint>
    <actuator name="back_wheel_LMotor">
      <hardwareInterface>hardware_interface/EffortJointInterface</hardwareInterface>
      <mechanicalReduction>1</mechanicalReduction>
    </actuator>
  </transmission>
  <!-- END BACK WHEEL LEFT -->
  <link name="right_axis">
    <collision>
      <origin rpy="0 0 0" xyz="0 0 0"/>
      <geometry>
        <mesh filename="package://curiosity_mars_rover_description/meshes/right_axis_jointfix_v2.dae" scale="1.0 1.0 1.0"/>
      </geometry>
    </collision>
    <visual>
      <origin rpy="0 0 0" xyz="0 0 0"/>
      <geometry>
        <mesh filename="package://curiosity_mars_rover_description/meshes/right_axis_jointfix_v2.dae" scale="1.0 1.0 1.0"/>
      </geometry>
    </visual>
    <inertial>
      <origin rpy="0 0 0" xyz="0 0 0"/>
      <mass value="7.296"/>
      <inertia ixx="0.105611398768" ixy="0" ixz="0" iyy="0.125057783795" iyz="0" izz="0.125057783795"/>
    </inertial>
  </link>
  <joint name="right_axis_joint" type="fixed">
    <parent link="chassis"/>
    <child link="right_axis"/>
    <origin rpy="0 0.19565141 0" xyz="-0.7938 -0.2133 0"/>
  </joint>
  <link name="suspension_arm_F_R">
    <collision>
      <origin rpy="0 0 0" xyz="0 0 0"/>
      <geometry>
        <mesh filename="package://curiosity_mars_rover_description/meshes/suspension_arm_F_R_fixed.dae" scale="1.0 1.0 1.0"/>
      </geometry>
    </collision>
    <visual>
      <origin rpy="0 0 0" xyz="0 0 0"/>
      <geometry>
        <mesh filename="package://curiosity_mars_rover_description/meshes/suspension_arm_F_R_fixed.dae" scale="1.0 1.0 1.0"/>
      </geometry>
    </visual>
    <inertial>
      <origin rpy="0 0 0" xyz="0 0 0"/>
      <mass value="7.296"/>
      <inertia ixx="0.691776350704" ixy="0" ixz="0" iyy="0.152065817946" iyz="0" izz="0.152065817946"/>
    </inertial>
  </link>
  <joint name="suspension_arm_F_R_joint" type="revolute">
    <parent link="right_axis"/>
    <child link="suspension_arm_F_R"/>
    <origin rpy="0 0 0" xyz="0 0 0"/>
    <limit effort="10000.0" lower="-0.4" upper="0.4" velocity="10.0"/>
    <axis xyz="1 0 0"/>
    <joint_properties damping="0.5" friction="0.5"/>
  </joint>
  <transmission name="suspension_arm_F_R_trans">
    <type>transmission_interface/SimpleTransmission</type>
    <joint name="suspension_arm_F_R_joint">
      <hardwareInterface>hardware_interface/EffortJointInterface</hardwareInterface>
    </joint>
    <actuator name="suspension_arm_F_RMotor">
      <hardwareInterface>hardware_interface/EffortJointInterface</hardwareInterface>
      <mechanicalReduction>1</mechanicalReduction>
    </actuator>
  </transmission>
  <link name="suspension_arm_B_R">
    <collision>
      <origin rpy="0 0 0" xyz="0 0 0"/>
      <geometry>
        <mesh filename="package://curiosity_mars_rover_description/meshes/suspension_arm_B_R_fixed.dae" scale="1.0 1.0 1.0"/>
      </geometry>
    </collision>
    <visual>
      <origin rpy="0 0 0" xyz="0 0 0"/>
      <geometry>
        <mesh filename="package://curiosity_mars_rover_description/meshes/suspension_arm_B_R_fixed.dae" scale="1.0 1.0 1.0"/>
      </geometry>
    </visual>
    <inertial>
      <origin rpy="0 0 0" xyz="0 0 0"/>
      <mass value="7.296"/>
      <inertia ixx="0.515242640212" ixy="0" ixz="0" iyy="0.0830580822383" iyz="0" izz="0.0830580822383"/>
    </inertial>
  </link>
  <joint name="suspension_arm_B_R_joint" type="revolute">
    <parent link="right_axis"/>
    <child link="suspension_arm_B_R"/>
    <origin rpy="0 0 0" xyz="0 0 0"/>
    <limit effort="10000.0" lower="-0.4" upper="0.4" velocity="10.0"/>
    <axis xyz="1 0 0"/>
    <joint_properties damping="0.5" friction="0.5"/>
  </joint>
  <transmission name="suspension_arm_B_R_trans">
    <type>transmission_interface/SimpleTransmission</type>
    <joint name="suspension_arm_B_R_joint">
      <hardwareInterface>hardware_interface/EffortJointInterface</hardwareInterface>
    </joint>
    <actuator name="suspension_arm_B_RMotor">
      <hardwareInterface>hardware_interface/EffortJointInterface</hardwareInterface>
      <mechanicalReduction>1</mechanicalReduction>
    </actuator>
  </transmission>
  <link name="suspension_arm_B_R_to_B2_R">
    <inertial>
      <origin rpy="0 0 0" xyz="0 0 0"/>
      <mass value="0.02"/>
      <inertia ixx="2.61666666667e-05" ixy="0.0" ixz="0.0" iyy="2.61666666667e-05" iyz="0.0" izz="3.6e-05"/>
    </inertial>
    <collision>
      <origin rpy="0 0 0" xyz="0 0 0.015"/>
      <geometry>
        <cylinder length="0.035" radius="0.06"/>
      </geometry>
    </collision>
    <visual>
      <origin rpy="0.0 1.57 0" xyz="0 0 0"/>
      <geometry>
        <cylinder length="0.1" radius="0.04"/>
      </geometry>
    </visual>
  </link>
  <joint name="suspension_arm_B_R_to_B2_R_joint" type="fixed">
    <parent link="suspension_arm_B_R"/>
    <child link="suspension_arm_B_R_to_B2_R"/>
    <origin rpy="0 -0.1937315 0" xyz="0.05159 0.73683 -0.22972"/>
  </joint>
  <link name="suspension_arm_B2_R">
    <collision>
      <origin rpy="0 0 0" xyz="0 0 0"/>
      <geometry>
        <mesh filename="package://curiosity_mars_rover_description/meshes/suspension_arm_B2_R_fixed.dae" scale="1.0 1.0 1.0"/>
      </geometry>
    </collision>
    <visual>
      <origin rpy="0 0 0" xyz="0 0 0"/>
      <geometry>
        <mesh filename="package://curiosity_mars_rover_description/meshes/suspension_arm_B2_R_fixed.dae" scale="1.0 1.0 1.0"/>
      </geometry>
    </visual>
    <inertial>
      <origin rpy="0 0 0" xyz="0 0 0"/>
      <mass value="7.296"/>
      <inertia ixx="1.14896565746" ixy="0" ixz="0" iyy="0.339748782044" iyz="0" izz="0.339748782044"/>
    </inertial>
  </link>
  <joint name="suspension_arm_B2_R_joint" type="revolute">
    <parent link="suspension_arm_B_R_to_B2_R"/>
    <child link="suspension_arm_B2_R"/>
    <origin rpy="0 0 0" xyz="0 0 0"/>
    <limit effort="10000.0" lower="-1.2" upper="0.1" velocity="10.0"/>
    <axis xyz="1 0 0"/>
    <joint_properties damping="0.5" friction="0.5"/>
  </joint>
  <transmission name="suspension_arm_B2_R_trans">
    <type>transmission_interface/SimpleTransmission</type>
    <joint name="suspension_arm_B2_R_joint">
      <hardwareInterface>hardware_interface/EffortJointInterface</hardwareInterface>
    </joint>
    <actuator name="suspension_arm_B2_RMotor">
      <hardwareInterface>hardware_interface/EffortJointInterface</hardwareInterface>
      <mechanicalReduction>1</mechanicalReduction>
    </actuator>
  </transmission>
  <!-- FRONT WHEEL RIGHT -->
  <link name="suspension_arm_F_R_to_suspension_steer_F_R">
    <inertial>
      <origin rpy="0 0 0" xyz="0 0 0"/>
      <mass value="0.02"/>
      <inertia ixx="2.61666666667e-05" ixy="0.0" ixz="0.0" iyy="2.61666666667e-05" iyz="0.0" izz="3.6e-05"/>
    </inertial>
    <collision>
      <origin rpy="0 0 0" xyz="0 0 0.015"/>
      <geometry>
        <cylinder length="0.04" radius="0.06"/>
      </geometry>
    </collision>
    <visual>
      <origin rpy="0.0 0 0" xyz="0 0 0"/>
      <geometry>
        <cylinder length="0.04" radius="0.06"/>
      </geometry>
    </visual>
  </link>
  <joint name="suspension_arm_F_R_to_suspension_steer_F_R_joint" type="fixed">
    <parent link="suspension_arm_F_R"/>
    <child link="suspension_arm_F_R_to_suspension_steer_F_R"/>
    <origin rpy="0 -0.1937315 0" xyz="-0.2057 -0.87876 -0.29370"/>
  </joint>
  <link name="suspension_steer_F_R">
    <collision>
      <origin rpy="0 0 0" xyz="0 0 0"/>
      <geometry>
        <mesh filename="package://curiosity_mars_rover_description/meshes/suspension_steer_F_R_fixed.dae" scale="1.0 1.0 1.0"/>
      </geometry>
    </collision>
    <visual>
      <origin rpy="0 0 0" xyz="0 0 0"/>
      <geometry>
        <mesh filename="package://curiosity_mars_rover_description/meshes/suspension_steer_F_R_fixed.dae" scale="1.0 1.0 1.0"/>
      </geometry>
    </visual>
    <inertial>
      <origin rpy="0 0 0" xyz="0 0 0"/>
      <mass value="7.296"/>
      <inertia ixx="0.150001040337" ixy="0" ixz="0" iyy="0.292896645934" iyz="0" izz="0.292896645934"/>
    </inertial>
  </link>
  <joint name="suspension_steer_F_R_joint" type="revolute">
    <parent link="suspension_arm_F_R_to_suspension_steer_F_R"/>
    <child link="suspension_steer_F_R"/>
    <origin rpy="0 0 0" xyz="0 0 0"/>
    <limit effort="10000.0" lower="-0.6" upper="0.6" velocity="10.0"/>
    <axis xyz="0 0 1"/>
  </joint>
  <transmission name="suspension_steer_F_R_trans">
    <type>transmission_interface/SimpleTransmission</type>
    <joint name="suspension_steer_F_R_joint">
      <hardwareInterface>hardware_interface/EffortJointInterface</hardwareInterface>
    </joint>
    <actuator name="suspension_steer_F_RMotor">
      <hardwareInterface>hardware_interface/EffortJointInterface</hardwareInterface>
      <mechanicalReduction>1</mechanicalReduction>
    </actuator>
  </transmission>
  <link name="suspension_steer_F_R_to_front_wheel_R">
    <inertial>
      <origin rpy="0 0 0" xyz="0 0 0"/>
      <mass value="0.02"/>
      <inertia ixx="2.61666666667e-05" ixy="0.0" ixz="0.0" iyy="2.61666666667e-05" iyz="0.0" izz="3.6e-05"/>
    </inertial>
    <collision>
      <origin rpy="0.0 1.57 0" xyz="0 0 0"/>
      <geometry>
        <cylinder length="0.02" radius="0.02"/>
      </geometry>
    </collision>
    <visual>
      <origin rpy="0.0 1.57 0" xyz="0 0 0"/>
      <geometry>
        <cylinder length="0.02" radius="0.02"/>
      </geometry>
    </visual>
  </link>
  <joint name="suspension_steer_F_R_to_suspension_steer_F_R_to_front_wheel_R_joint" type="fixed">
    <parent link="suspension_steer_F_R"/>
    <child link="suspension_steer_F_R_to_front_wheel_R"/>
    <origin rpy="0 0 0" xyz="0 0 -0.3996"/>
  </joint>
  <!-- tY is Zero if left side, 1 if right side -->
  <link name="front_wheel_R">
    <collision>
      <origin rpy="0 1.57 0" xyz="0 0 0"/>
      <geometry>
        <cylinder length="0.39473" radius="0.242647"/>
      </geometry>
    </collision>
    <visual>
      <origin rpy="0 0 0" xyz="0 0 0"/>
      <geometry>
        <mesh filename="package://curiosity_mars_rover_description/meshes/wheel_fixed.dae" scale="1.0 1.0 1.0"/>
      </geometry>
    </visual>
    <inertial>
      <origin rpy="0 0 0" xyz="0 0 0"/>
      <mass value="2.07"/>
      <inertia ixx="0.0573466715454" ixy="0" ixz="0" iyy="0.0573466715454" iyz="0" izz="0.0609382814403"/>
    </inertial>
  </link>
  <gazebo reference="front_wheel_R">
    <mu1 value="1.0"/>
    <mu2 value="1.0"/>
    <kp value="10000000.0"/>
    <kd>100.0</kd>
    <minDepth>0.001</minDepth>
    <maxVel>1.0</maxVel>
    <!--kd  value="1.0" />
      <fdir1 value="1 0 0"/-->
  </gazebo>
  <joint name="front_wheel_R_joint" type="continuous">
    <parent link="suspension_steer_F_R_to_front_wheel_R"/>
    <child link="front_wheel_R"/>
    <origin rpy="0 0 -3.14159265359" xyz="0 0 0"/>
    <limit effort="10000.0" velocity="100.0"/>
    <axis xyz="1 0 0"/>
    <joint_properties damping="0.0" friction="0.0"/>
  </joint>
  <transmission name="front_wheel_R_trans">
    <type>transmission_interface/SimpleTransmission</type>
    <joint name="front_wheel_R_joint">
      <hardwareInterface>hardware_interface/EffortJointInterface</hardwareInterface>
    </joint>
    <actuator name="front_wheel_RMotor">
      <hardwareInterface>hardware_interface/EffortJointInterface</hardwareInterface>
      <mechanicalReduction>1</mechanicalReduction>
    </actuator>
  </transmission>
  <!-- FRONT WHEEL RIGHT END -->
  <link name="suspension_arm_B2_R_to_middle_wheel_R">
    <inertial>
      <origin rpy="0 0 0" xyz="0 0 0"/>
      <mass value="0.02"/>
      <inertia ixx="2.61666666667e-05" ixy="0.0" ixz="0.0" iyy="2.61666666667e-05" iyz="0.0" izz="3.6e-05"/>
    </inertial>
    <collision>
      <origin rpy="0.0 1.57 0" xyz="0 0 0"/>
      <geometry>
        <cylinder length="0.02" radius="0.02"/>
      </geometry>
    </collision>
    <visual>
      <origin rpy="0.0 1.57 0" xyz="0 0 0"/>
      <geometry>
        <cylinder length="0.02" radius="0.02"/>
      </geometry>
    </visual>
  </link>
  <joint name="suspension_arm_B2_R_to_suspension_arm_B2_R_to_middle_wheel_R_joint" type="fixed">
    <parent link="suspension_arm_B2_R"/>
    <child link="suspension_arm_B2_R_to_middle_wheel_R"/>
    <origin rpy="0 0 0" xyz="-0.39423 -0.44859 -0.41098"/>
  </joint>
  <!-- tY is Zero if left side, 1 if right side -->
  <link name="middle_wheel_R">
    <collision>
      <origin rpy="0 1.57 0" xyz="0 0 0"/>
      <geometry>
        <cylinder length="0.39473" radius="0.242647"/>
      </geometry>
    </collision>
    <visual>
      <origin rpy="0 0 0" xyz="0 0 0"/>
      <geometry>
        <mesh filename="package://curiosity_mars_rover_description/meshes/wheel_fixed.dae" scale="1.0 1.0 1.0"/>
      </geometry>
    </visual>
    <inertial>
      <origin rpy="0 0 0" xyz="0 0 0"/>
      <mass value="2.07"/>
      <inertia ixx="0.0573466715454" ixy="0" ixz="0" iyy="0.0573466715454" iyz="0" izz="0.0609382814403"/>
    </inertial>
  </link>
  <gazebo reference="middle_wheel_R">
    <mu1 value="1.0"/>
    <mu2 value="1.0"/>
    <kp value="10000000.0"/>
    <kd>100.0</kd>
    <minDepth>0.001</minDepth>
    <maxVel>1.0</maxVel>
    <!--kd  value="1.0" />
      <fdir1 value="1 0 0"/-->
  </gazebo>
  <joint name="middle_wheel_R_joint" type="continuous">
    <parent link="suspension_arm_B2_R_to_middle_wheel_R"/>
    <child link="middle_wheel_R"/>
    <origin rpy="0 0 -3.14159265359" xyz="0 0 0"/>
    <limit effort="10000.0" velocity="100.0"/>
    <axis xyz="1 0 0"/>
    <joint_properties damping="0.0" friction="0.0"/>
  </joint>
  <transmission name="middle_wheel_R_trans">
    <type>transmission_interface/SimpleTransmission</type>
    <joint name="middle_wheel_R_joint">
      <hardwareInterface>hardware_interface/EffortJointInterface</hardwareInterface>
    </joint>
    <actuator name="middle_wheel_RMotor">
      <hardwareInterface>hardware_interface/EffortJointInterface</hardwareInterface>
      <mechanicalReduction>1</mechanicalReduction>
    </actuator>
  </transmission>
  <!-- RIGHT BACK WHEEL -->
  <link name="suspension_arm_B2_R_to_suspension_steer_B_R">
    <inertial>
      <origin rpy="0 0 0" xyz="0 0 0"/>
      <mass value="0.02"/>
      <inertia ixx="2.61666666667e-05" ixy="0.0" ixz="0.0" iyy="2.61666666667e-05" iyz="0.0" izz="3.6e-05"/>
    </inertial>
    <collision>
      <origin rpy="0 0 0" xyz="0 0 0.015"/>
      <geometry>
        <cylinder length="0.04" radius="0.06"/>
      </geometry>
    </collision>
    <visual>
      <origin rpy="0.0 0 0" xyz="0 0 0"/>
      <geometry>
        <cylinder length="0.04" radius="0.06"/>
      </geometry>
    </visual>
  </link>
  <joint name="suspension_arm_B2_R_to_suspension_steer_B_R_joint" type="fixed">
    <parent link="suspension_arm_B2_R"/>
    <child link="suspension_arm_B2_R_to_suspension_steer_B_R"/>
    <origin rpy="0 0 0" xyz="-0.26271 0.62363 -0.00069"/>
  </joint>
  <link name="suspension_steer_B_R">
    <collision>
      <origin rpy="0 0 0" xyz="0 0 0"/>
      <geometry>
        <mesh filename="package://curiosity_mars_rover_description/meshes/suspension_steer_B_R_fixed.dae" scale="1.0 1.0 1.0"/>
      </geometry>
    </collision>
    <visual>
      <origin rpy="0 0 0" xyz="0 0 0"/>
      <geometry>
        <mesh filename="package://curiosity_mars_rover_description/meshes/suspension_steer_B_R_fixed.dae" scale="1.0 1.0 1.0"/>
      </geometry>
    </visual>
    <inertial>
      <origin rpy="0 0 0" xyz="0 0 0"/>
      <mass value="7.296"/>
      <inertia ixx="0.150001040337" ixy="0" ixz="0" iyy="0.292896645934" iyz="0" izz="0.292896645934"/>
    </inertial>
  </link>
  <joint name="suspension_steer_B_R_joint" type="revolute">
    <parent link="suspension_arm_B2_R_to_suspension_steer_B_R"/>
    <child link="suspension_steer_B_R"/>
    <origin rpy="0 0 0" xyz="0 0 0"/>
    <limit effort="10000.0" lower="-0.6" upper="0.6" velocity="10.0"/>
    <axis xyz="0 0 1"/>
  </joint>
  <transmission name="suspension_steer_B_R_trans">
    <type>transmission_interface/SimpleTransmission</type>
    <joint name="suspension_steer_B_R_joint">
      <hardwareInterface>hardware_interface/EffortJointInterface</hardwareInterface>
    </joint>
    <actuator name="suspension_steer_B_RMotor">
      <hardwareInterface>hardware_interface/EffortJointInterface</hardwareInterface>
      <mechanicalReduction>1</mechanicalReduction>
    </actuator>
  </transmission>
  <link name="suspension_steer_B_R_to_back_wheel_R">
    <inertial>
      <origin rpy="0 0 0" xyz="0 0 0"/>
      <mass value="0.02"/>
      <inertia ixx="2.61666666667e-05" ixy="0.0" ixz="0.0" iyy="2.61666666667e-05" iyz="0.0" izz="3.6e-05"/>
    </inertial>
    <collision>
      <origin rpy="0.0 1.57 0" xyz="0 0 0"/>
      <geometry>
        <cylinder length="0.02" radius="0.02"/>
      </geometry>
    </collision>
    <visual>
      <origin rpy="0.0 1.57 0" xyz="0 0 0"/>
      <geometry>
        <cylinder length="0.02" radius="0.02"/>
      </geometry>
    </visual>
  </link>
  <joint name="suspension_arm_B2_R_to_suspension_steer_B_R_to_back_wheel_R_joint" type="fixed">
    <parent link="suspension_steer_B_R"/>
    <child link="suspension_steer_B_R_to_back_wheel_R"/>
    <origin rpy="0 0 0" xyz="0 0 -0.410523"/>
  </joint>
  <!-- tY is Zero if left side, 1 if right side -->
  <link name="back_wheel_R">
    <collision>
      <origin rpy="0 1.57 0" xyz="0 0 0"/>
      <geometry>
        <cylinder length="0.39473" radius="0.242647"/>
      </geometry>
    </collision>
    <visual>
      <origin rpy="0 0 0" xyz="0 0 0"/>
      <geometry>
        <mesh filename="package://curiosity_mars_rover_description/meshes/wheel_fixed.dae" scale="1.0 1.0 1.0"/>
      </geometry>
    </visual>
    <inertial>
      <origin rpy="0 0 0" xyz="0 0 0"/>
      <mass value="2.07"/>
      <inertia ixx="0.0573466715454" ixy="0" ixz="0" iyy="0.0573466715454" iyz="0" izz="0.0609382814403"/>
    </inertial>
  </link>
  <gazebo reference="back_wheel_R">
    <mu1 value="1.0"/>
    <mu2 value="1.0"/>
    <kp value="10000000.0"/>
    <kd>100.0</kd>
    <minDepth>0.001</minDepth>
    <maxVel>1.0</maxVel>
    <!--kd  value="1.0" />
      <fdir1 value="1 0 0"/-->
  </gazebo>
  <joint name="back_wheel_R_joint" type="continuous">
    <parent link="suspension_steer_B_R_to_back_wheel_R"/>
    <child link="back_wheel_R"/>
    <origin rpy="0 0 -3.14159265359" xyz="0 0 0"/>
    <limit effort="10000.0" velocity="100.0"/>
    <axis xyz="1 0 0"/>
    <joint_properties damping="0.0" friction="0.0"/>
  </joint>
  <transmission name="back_wheel_R_trans">
    <type>transmission_interface/SimpleTransmission</type>
    <joint name="back_wheel_R_joint">
      <hardwareInterface>hardware_interface/EffortJointInterface</hardwareInterface>
    </joint>
    <actuator name="back_wheel_RMotor">
      <hardwareInterface>hardware_interface/EffortJointInterface</hardwareInterface>
      <mechanicalReduction>1</mechanicalReduction>
    </actuator>
  </transmission>
  <!-- END BACK WHEEL RIGHT -->
  <link name="chassis_to_arm_01">
    <inertial>
      <origin rpy="0 0 0" xyz="0 0 0"/>
      <mass value="0.02"/>
      <inertia ixx="2.61666666667e-05" ixy="0.0" ixz="0.0" iyy="2.61666666667e-05" iyz="0.0" izz="3.6e-05"/>
    </inertial>
    <collision>
      <origin rpy="0.0 1.57 0" xyz="0 0 0"/>
      <geometry>
        <cylinder length="0.02" radius="0.02"/>
      </geometry>
    </collision>
    <visual>
      <origin rpy="0.0 0 0" xyz="0 0 0"/>
      <geometry>
        <cylinder length="0.02" radius="0.02"/>
      </geometry>
    </visual>
  </link>
  <joint name="chassis_to_arm_01_joint" type="fixed">
    <parent link="chassis"/>
    <child link="chassis_to_arm_01"/>
    <origin rpy="0 0 0" xyz="0.449641 -1.11319 0.112807"/>
  </joint>
  <link name="arm_01">
    <collision>
      <origin rpy="0 0 0" xyz="0 0 0"/>
      <geometry>
        <mesh filename="package://curiosity_mars_rover_description/meshes/arm_01_fixed.dae" scale="1.0 1.0 1.0"/>
      </geometry>
    </collision>
    <visual>
      <origin rpy="0 0 0" xyz="0 0 0"/>
      <geometry>
        <mesh filename="package://curiosity_mars_rover_description/meshes/arm_01_fixed.dae" scale="1.0 1.0 1.0"/>
      </geometry>
    </visual>
    <inertial>
      <origin rpy="0 0 0" xyz="0 0 0"/>
      <mass value="6.0"/>
      <inertia ixx="0.100974190752" ixy="0" ixz="0" iyy="0.108839023501" iyz="0" izz="0.108839023501"/>
    </inertial>
  </link>
  <joint name="arm_01_joint" type="revolute">
    <parent link="chassis_to_arm_01"/>
    <child link="arm_01"/>
    <origin rpy="0 0 0" xyz="0 0 0"/>
    <limit effort="10000.0" lower="-1.57" upper="1.57" velocity="100.0"/>
    <axis xyz="0 0 1"/>
    <joint_properties damping="0.0" friction="0.0"/>
  </joint>
  <transmission name="arm_01_trans">
    <type>transmission_interface/SimpleTransmission</type>
    <joint name="arm_01_joint">
      <hardwareInterface>hardware_interface/EffortJointInterface</hardwareInterface>
    </joint>
    <actuator name="arm_01Motor">
      <hardwareInterface>hardware_interface/EffortJointInterface</hardwareInterface>
      <mechanicalReduction>1</mechanicalReduction>
    </actuator>
  </transmission>
  <link name="arm_01_to_arm_02">
    <inertial>
      <origin rpy="0 0 0" xyz="0 0 0"/>
      <mass value="0.02"/>
      <inertia ixx="2.61666666667e-05" ixy="0.0" ixz="0.0" iyy="2.61666666667e-05" iyz="0.0" izz="3.6e-05"/>
    </inertial>
    <collision>
      <origin rpy="0.0 1.57 0" xyz="0 0 0"/>
      <geometry>
        <cylinder length="0.02" radius="0.02"/>
      </geometry>
    </collision>
    <visual>
      <origin rpy="0.0 0 0" xyz="0 0 0"/>
      <geometry>
        <cylinder length="0.02" radius="0.02"/>
      </geometry>
    </visual>
  </link>
  <joint name="arm_01_to_arm_02_joint" type="fixed">
    <parent link="arm_01"/>
    <child link="arm_01_to_arm_02"/>
    <origin rpy="0 0 0" xyz="0.0 -0.160259 -0.166117"/>
  </joint>
  <link name="arm_02">
    <collision>
      <origin rpy="0 0 0" xyz="0 0 0"/>
      <geometry>
        <mesh filename="package://curiosity_mars_rover_description/meshes/arm_02_fixed.dae" scale="1.0 1.0 1.0"/>
      </geometry>
    </collision>
    <visual>
      <origin rpy="0 0 0" xyz="0 0 0"/>
      <geometry>
        <mesh filename="package://curiosity_mars_rover_description/meshes/arm_02_fixed.dae" scale="1.0 1.0 1.0"/>
      </geometry>
    </visual>
    <inertial>
      <origin rpy="0 0 0" xyz="0 0 0"/>
      <mass value="6.0"/>
      <inertia ixx="0.496591669645" ixy="0" ixz="0" iyy="0.135368111281" iyz="0" izz="0.135368111281"/>
    </inertial>
  </link>
  <joint name="arm_02_joint" type="revolute">
    <parent link="arm_01_to_arm_02"/>
    <child link="arm_02"/>
    <origin rpy="0 0 0" xyz="0 0 0"/>
    <limit effort="10000.0" lower="-1.57" upper="1.57" velocity="100.0"/>
    <axis xyz="1 0 0"/>
    <joint_properties damping="0.0" friction="0.0"/>
  </joint>
  <transmission name="arm_02_trans">
    <type>transmission_interface/SimpleTransmission</type>
    <joint name="arm_02_joint">
      <hardwareInterface>hardware_interface/EffortJointInterface</hardwareInterface>
    </joint>
    <actuator name="arm_02Motor">
      <hardwareInterface>hardware_interface/EffortJointInterface</hardwareInterface>
      <mechanicalReduction>1</mechanicalReduction>
    </actuator>
  </transmission>
  <link name="arm_02_to_arm_03">
    <inertial>
      <origin rpy="0 0 0" xyz="0 0 0"/>
      <mass value="0.02"/>
      <inertia ixx="2.61666666667e-05" ixy="0.0" ixz="0.0" iyy="2.61666666667e-05" iyz="0.0" izz="3.6e-05"/>
    </inertial>
    <collision>
      <origin rpy="0.0 1.57 0" xyz="0 0 0"/>
      <geometry>
        <cylinder length="0.02" radius="0.02"/>
      </geometry>
    </collision>
    <visual>
      <origin rpy="0.0 0 0" xyz="0 0 0"/>
      <geometry>
        <cylinder length="0.02" radius="0.02"/>
      </geometry>
    </visual>
  </link>
  <joint name="arm_02_to_arm_03_joint" type="fixed">
    <parent link="arm_02"/>
    <child link="arm_02_to_arm_03"/>
    <origin rpy="0 0 0" xyz="0.071249 -0.825069 0.0"/>
  </joint>
  <link name="arm_03">
    <collision>
      <origin rpy="0 0 0" xyz="0 0 0"/>
      <geometry>
        <mesh filename="package://curiosity_mars_rover_description/meshes/arm_03_fixed.dae" scale="1.0 1.0 1.0"/>
      </geometry>
    </collision>
    <visual>
      <origin rpy="0 0 0" xyz="0 0 0"/>
      <geometry>
        <mesh filename="package://curiosity_mars_rover_description/meshes/arm_03_fixed.dae" scale="1.0 1.0 1.0"/>
      </geometry>
    </visual>
    <inertial>
      <origin rpy="0 0 0" xyz="0 0 0"/>
      <mass value="6.0"/>
      <inertia ixx="0.402233813106" ixy="0" ixz="0" iyy="0.433355907332" iyz="0" izz="0.433355907332"/>
    </inertial>
  </link>
  <joint name="arm_03_joint" type="revolute">
    <parent link="arm_02_to_arm_03"/>
    <child link="arm_03"/>
    <origin rpy="0 0 0" xyz="0 0 0"/>
    <limit effort="10000.0" lower="-1.57" upper="1.57" velocity="100.0"/>
    <axis xyz="1 0 0"/>
    <joint_properties damping="0.0" friction="0.0"/>
  </joint>
  <transmission name="arm_03_trans">
    <type>transmission_interface/SimpleTransmission</type>
    <joint name="arm_03_joint">
      <hardwareInterface>hardware_interface/EffortJointInterface</hardwareInterface>
    </joint>
    <actuator name="arm_03Motor">
      <hardwareInterface>hardware_interface/EffortJointInterface</hardwareInterface>
      <mechanicalReduction>1</mechanicalReduction>
    </actuator>
  </transmission>
  <link name="arm_03_to_arm_04">
    <inertial>
      <origin rpy="0 0 0" xyz="0 0 0"/>
      <mass value="0.02"/>
      <inertia ixx="2.61666666667e-05" ixy="0.0" ixz="0.0" iyy="2.61666666667e-05" iyz="0.0" izz="3.6e-05"/>
    </inertial>
    <collision>
      <origin rpy="1.57 0 0" xyz="0 0 0"/>
      <geometry>
        <cylinder length="0.02" radius="0.02"/>
      </geometry>
    </collision>
    <visual>
      <origin rpy="1.57 0 0" xyz="0 0 0"/>
      <geometry>
        <cylinder length="0.02" radius="0.02"/>
      </geometry>
    </visual>
  </link>
  <joint name="arm_03_to_arm_04_joint" type="fixed">
    <parent link="arm_03"/>
    <child link="arm_03_to_arm_04"/>
    <origin rpy="0 0 1.57079632679" xyz="-0.193815 0.0 0.779746"/>
  </joint>
  <link name="arm_04">
    <collision>
      <origin rpy="0 0 0" xyz="0 0 0"/>
      <geometry>
        <mesh filename="package://curiosity_mars_rover_description/meshes/arm_04_fixed.dae" scale="1.0 1.0 1.0"/>
      </geometry>
    </collision>
    <visual>
      <origin rpy="0 0 0" xyz="0 0 0"/>
      <geometry>
        <mesh filename="package://curiosity_mars_rover_description/meshes/arm_04_fixed.dae" scale="1.0 1.0 1.0"/>
      </geometry>
    </visual>
    <inertial>
      <origin rpy="0 0 0" xyz="0 0 0"/>
      <mass value="6.0"/>
      <inertia ixx="0.101118594236" ixy="0" ixz="0" iyy="0.094368577312" iyz="0" izz="0.094368577312"/>
    </inertial>
  </link>
  <joint name="arm_04_joint" type="revolute">
    <parent link="arm_03_to_arm_04"/>
    <child link="arm_04"/>
    <origin rpy="0 0 0" xyz="0 0 0"/>
    <limit effort="10000.0" lower="-1.57" upper="1.57" velocity="100.0"/>
    <axis xyz="0 1 0"/>
    <joint_properties damping="0.0" friction="0.0"/>
  </joint>
  <transmission name="arm_04_trans">
    <type>transmission_interface/SimpleTransmission</type>
    <joint name="arm_04_joint">
      <hardwareInterface>hardware_interface/EffortJointInterface</hardwareInterface>
    </joint>
    <actuator name="arm_04Motor">
      <hardwareInterface>hardware_interface/EffortJointInterface</hardwareInterface>
      <mechanicalReduction>1</mechanicalReduction>
    </actuator>
  </transmission>
  <link name="arm_04_to_arm_tools">
    <inertial>
      <origin rpy="0 0 0" xyz="0 0 0"/>
      <mass value="0.02"/>
      <inertia ixx="2.61666666667e-05" ixy="0.0" ixz="0.0" iyy="2.61666666667e-05" iyz="0.0" izz="3.6e-05"/>
    </inertial>
    <collision>
      <origin rpy="0 0 0" xyz="0 0 0"/>
      <geometry>
        <cylinder length="0.02" radius="0.02"/>
      </geometry>
    </collision>
    <visual>
      <origin rpy="0 0 0" xyz="0 0 0"/>
      <geometry>
        <cylinder length="0.02" radius="0.02"/>
      </geometry>
    </visual>
  </link>
  <joint name="arm_04_to_arm_tools_joint" type="fixed">
    <parent link="arm_04"/>
    <child link="arm_04_to_arm_tools"/>
    <origin rpy="0 0 0" xyz="0.141321 0.042652 0.105732"/>
  </joint>
  <link name="arm_tools">
    <collision>
      <origin rpy="0 0 0" xyz="0 0 0"/>
      <geometry>
        <mesh filename="package://curiosity_mars_rover_description/meshes/arm_tools_fixed.dae" scale="1.0 1.0 1.0"/>
      </geometry>
    </collision>
    <visual>
      <origin rpy="0 0 0" xyz="0 0 0"/>
      <geometry>
        <mesh filename="package://curiosity_mars_rover_description/meshes/arm_tools_fixed.dae" scale="1.0 1.0 1.0"/>
      </geometry>
    </visual>
    <inertial>
      <origin rpy="0 0 0" xyz="0 0 0"/>
      <mass value="6.0"/>
      <inertia ixx="0.133126521055" ixy="0" ixz="0" iyy="0.20570933745" iyz="0" izz="0.20570933745"/>
    </inertial>
  </link>
  <joint name="arm_tools_joint" type="continuous">
    <parent link="arm_04_to_arm_tools"/>
    <child link="arm_tools"/>
    <origin rpy="0 0 0" xyz="0 0 0"/>
    <limit effort="10000.0" velocity="100.0"/>
    <axis xyz="0 0 1"/>
    <joint_properties damping="0.0" friction="0.0"/>
  </joint>
  <transmission name="arm_tools_trans">
    <type>transmission_interface/SimpleTransmission</type>
    <joint name="arm_tools_joint">
      <hardwareInterface>hardware_interface/EffortJointInterface</hardwareInterface>
    </joint>
    <actuator name="arm_toolsMotor">
      <hardwareInterface>hardware_interface/EffortJointInterface</hardwareInterface>
      <mechanicalReduction>1</mechanicalReduction>
    </actuator>
  </transmission>
  <link name="chassis_to_mast_p">
    <inertial>
      <origin rpy="0 0 0" xyz="0 0 0"/>
      <mass value="0.02"/>
      <inertia ixx="2.61666666667e-05" ixy="0.0" ixz="0.0" iyy="2.61666666667e-05" iyz="0.0" izz="3.6e-05"/>
    </inertial>
    <collision>
      <origin rpy="1.57 0 0" xyz="0 0 0"/>
      <geometry>
        <cylinder length="0.02" radius="0.02"/>
      </geometry>
    </collision>
    <visual>
      <origin rpy="1.57 0 0" xyz="0 0 0"/>
      <geometry>
        <cylinder length="0.02" radius="0.02"/>
      </geometry>
    </visual>
  </link>
  <joint name="chassis_to_mast_p_joint" type="fixed">
    <parent link="chassis"/>
    <child link="chassis_to_mast_p"/>
    <origin rpy="0 0 0.523599" xyz="-0.55456 -0.722499 0.331395"/>
  </joint>
  <link name="mast_p">
    <collision>
      <origin rpy="0 0 0" xyz="0 0 0"/>
      <geometry>
        <mesh filename="package://curiosity_mars_rover_description/meshes/mast_p_fixed.dae" scale="1.0 1.0 1.0"/>
      </geometry>
    </collision>
    <visual>
      <origin rpy="0 0 0" xyz="0 0 0"/>
      <geometry>
        <mesh filename="package://curiosity_mars_rover_description/meshes/mast_p_fixed.dae" scale="1.0 1.0 1.0"/>
      </geometry>
    </visual>
    <inertial>
      <origin rpy="0 0 0" xyz="0 0 0"/>
      <mass value="16.6666666667"/>
      <inertia ixx="0.451856982885" ixy="0" ixz="0" iyy="0.435064898218" iyz="0" izz="0.435064898218"/>
    </inertial>
  </link>
  <joint name="mast_p_joint" type="revolute">
    <parent link="chassis_to_mast_p"/>
    <child link="mast_p"/>
    <origin rpy="0 0 0" xyz="0 0 0"/>
    <limit effort="10000.0" lower="0.0" upper="1.57" velocity="100.0"/>
    <axis xyz="0 1 0"/>
    <joint_properties damping="0.0" friction="0.0"/>
  </joint>
  <transmission name="mast_p_trans">
    <type>transmission_interface/SimpleTransmission</type>
    <joint name="mast_p_joint">
      <hardwareInterface>hardware_interface/EffortJointInterface</hardwareInterface>
    </joint>
    <actuator name="mast_pMotor">
      <hardwareInterface>hardware_interface/EffortJointInterface</hardwareInterface>
      <mechanicalReduction>1</mechanicalReduction>
    </actuator>
  </transmission>
  <link name="mast_p_to_mast_02">
    <inertial>
      <origin rpy="0 0 0" xyz="0 0 0"/>
      <mass value="0.02"/>
      <inertia ixx="2.61666666667e-05" ixy="0.0" ixz="0.0" iyy="2.61666666667e-05" iyz="0.0" izz="3.6e-05"/>
    </inertial>
    <collision>
      <origin rpy="0 0 0" xyz="0 0 0"/>
      <geometry>
        <cylinder length="0.02" radius="0.02"/>
      </geometry>
    </collision>
    <visual>
      <origin rpy="0 0 0" xyz="0 0 0"/>
      <geometry>
        <cylinder length="0.02" radius="0.02"/>
      </geometry>
    </visual>
  </link>
  <joint name="mast_p_to_mast_02_joint" type="fixed">
    <parent link="mast_p"/>
    <child link="mast_p_to_mast_02"/>
    <origin rpy="0 0 0" xyz="0 0 0.473641"/>
  </joint>
  <link name="mast_02">
    <collision>
      <origin rpy="0 0 0" xyz="0 0 0"/>
      <geometry>
        <mesh filename="package://curiosity_mars_rover_description/meshes/mast_02_fixed.dae" scale="1.0 1.0 1.0"/>
      </geometry>
    </collision>
    <visual>
      <origin rpy="0 0 0" xyz="0 0 0"/>
      <geometry>
        <mesh filename="package://curiosity_mars_rover_description/meshes/mast_02_fixed.dae" scale="1.0 1.0 1.0"/>
      </geometry>
    </visual>
    <inertial>
      <origin rpy="0 0 0" xyz="0 0 0"/>
      <mass value="16.6666666667"/>
      <inertia ixx="0.18840199059" ixy="0" ixz="0" iyy="0.215560027701" iyz="0" izz="0.215560027701"/>
    </inertial>
  </link>
  <joint name="mast_02_joint" type="continuous">
    <parent link="mast_p_to_mast_02"/>
    <child link="mast_02"/>
    <origin rpy="0 0 0" xyz="0 0 0"/>
    <limit effort="10000.0" velocity="100.0"/>
    <axis xyz="0 0 1"/>
    <joint_properties damping="0.0" friction="0.0"/>
  </joint>
  <transmission name="mast_02_trans">
    <type>transmission_interface/SimpleTransmission</type>
    <joint name="mast_02_joint">
      <hardwareInterface>hardware_interface/EffortJointInterface</hardwareInterface>
    </joint>
    <actuator name="mast_02Motor">
      <hardwareInterface>hardware_interface/EffortJointInterface</hardwareInterface>
      <mechanicalReduction>1</mechanicalReduction>
    </actuator>
  </transmission>
  <link name="mast_02_to_mast_cameras">
    <inertial>
      <origin rpy="0 0 0" xyz="0 0 0"/>
      <mass value="0.02"/>
      <inertia ixx="2.61666666667e-05" ixy="0.0" ixz="0.0" iyy="2.61666666667e-05" iyz="0.0" izz="3.6e-05"/>
    </inertial>
    <collision>
      <origin rpy="0 0 0" xyz="0 0 0"/>
      <geometry>
        <cylinder length="0.02" radius="0.02"/>
      </geometry>
    </collision>
    <visual>
      <origin rpy="0 0 0" xyz="0 0 0"/>
      <geometry>
        <cylinder length="0.02" radius="0.02"/>
      </geometry>
    </visual>
  </link>
  <joint name="mast_02_to_mast_cameras_joint" type="fixed">
    <parent link="mast_02"/>
    <child link="mast_02_to_mast_cameras"/>
    <origin rpy="0 0 0" xyz="0 0 0.20859"/>
  </joint>
  <link name="mast_cameras">
    <collision>
      <origin rpy="0 0 0" xyz="0 0 0"/>
      <geometry>
        <mesh filename="package://curiosity_mars_rover_description/meshes/mast_cameras.dae" scale="1.0 1.0 1.0"/>
      </geometry>
    </collision>
    <visual>
      <origin rpy="0 0 0" xyz="0 0 0"/>
      <geometry>
        <mesh filename="package://curiosity_mars_rover_description/meshes/mast_cameras.dae" scale="1.0 1.0 1.0"/>
      </geometry>
    </visual>
    <inertial>
      <origin rpy="0 0 0" xyz="0 0 0"/>
      <mass value="16.6666666667"/>
      <inertia ixx="0.169032108385" ixy="0" ixz="0" iyy="0.477937016718" iyz="0" izz="0.477937016718"/>
    </inertial>
  </link>
  <joint name="mast_cameras_joint" type="revolute">
    <parent link="mast_02_to_mast_cameras"/>
    <child link="mast_cameras"/>
    <origin rpy="0 0 0" xyz="0 0 0"/>
    <limit effort="10000.0" lower="-1.57" upper="1.57" velocity="100.0"/>
    <axis xyz="1 0 0"/>
    <joint_properties damping="0.0" friction="0.0"/>
  </joint>
  <transmission name="mast_02_trans">
    <type>transmission_interface/SimpleTransmission</type>
    <joint name="mast_cameras_joint">
      <hardwareInterface>hardware_interface/EffortJointInterface</hardwareInterface>
    </joint>
    <actuator name="mast_02Motor">
      <hardwareInterface>hardware_interface/EffortJointInterface</hardwareInterface>
      <mechanicalReduction>1</mechanicalReduction>
    </actuator>
  </transmission>
  <material name="green">
    <color rgba="0 0.8 0 1"/>
  </material>
  <link name="camera_link">
    <!-- Inertial for gazebo to take it into account, Put 1gr weight -->
    <inertial>
      <origin rpy="0 0 0" xyz="0 0 0"/>
      <mass value="0.001"/>
      <inertia ixx="9.1875e-09" ixy="0.0" ixz="0.0" iyy="9.1875e-09" iyz="0.0" izz="1.378125e-08"/>
    </inertial>
    <visual>
      <origin rpy="0.0 0 0" xyz="0 0 0"/>
      <geometry>
        <box size="0.0005 0.0005 0.0005"/>
      </geometry>
      <material name="green"/>
    </visual>
  </link>
  <gazebo reference="camera_link">
    <material>Gazebo/Green</material>
  </gazebo>
  <joint name="head_camera_joint" type="fixed">
    <parent link="mast_cameras"/>
    <child link="camera_link"/>
    <origin rpy="0 0 3.14159265359" xyz="0.13642 -0.218683 0.222314"/>
  </joint>
</robot>
